<?xml version="1.0"?>
<robot name="servicebot">

  <!-- Note: this doesnt follow REP 120 as this robot, while having a humanoid shape, will behave like a mobile base -->

  <link name="base_footprint">
  </link>

  <joint name="base_footprint_joint" type="fixed">
    <parent
      link="base_footprint"
    />
    <child
      link="base_link"
    />
    <origin rpy="0 0 0" xyz="0 0 0.749"/>
  </joint>

  <!-- setting the base_link as the center of mass of the torso -->
  <link name="base_link">
    <visual>
      <geometry>
        <mesh filename="package://servicebot_description/meshes/Torso.obj" />
      </geometry>
    </visual>
    <collision>
      <origin rpy="0 0 0" xyz="0 0 0.03"/>
      <geometry>
        <box size="0.32 0.3 0.32"/>
      </geometry>
    </collision>
    <collision>
      <origin rpy="0 0 0" xyz="0 0 0.23"/>
      <geometry>
        <cylinder radius="0.07" length="0.10"/>
      </geometry>
    </collision>
    <inertial>
      <origin rpy="0 0 0" xyz="-0.0 0 -2.20"/>
      <mass value="3"/>
      <inertia ixx="0.04167984" iyy="0.04167984" izz="0.03650587" ixy="0" ixz="0" iyz="0"/>
    </inertial>
  </link>

  <link name="head_link">
    <visual>
      <geometry>
        <mesh filename="package://servicebot_description/meshes/Head.obj" />
      </geometry>
    </visual>
    <collision>
      <origin rpy="0 0 0" xyz="0.01 0 0"/>
      <geometry>
        <sphere radius="0.13"/>
      </geometry>
    </collision>
    <inertial>
      <mass value="0.5"/>
      <inertia ixx="0.00338" iyy="0.00338" izz="0.00338" ixy="0" ixz="0.0" iyz="0"/>
    </inertial>
  </link>

  <joint name="head_tilt_joint" type="revolute">
    <axis xyz="0 -1 0"/>
    <parent link="head_pan_link"/>
    <child link="head_link"/>
    <origin rpy="0 0 0" xyz="0 0 0"/>
    <limit effort="30" velocity="1.0" lower="-0.7853981633974483" upper="0.7853981633974483" />
  </joint>

  <link name="head_pan_link">
    <inertial>
      <mass value="0.5"/>
      <inertia ixx="0.00338" iyy="0.00338" izz="0.00338" ixy="0" ixz="0.0" iyz="0"/>
    </inertial>
  </link>

  <joint name="head_pan_joint" type="revolute">
    <axis xyz="0 0 -1"/>
    <parent link="base_link"/>
    <child link="head_pan_link"/>
    <origin rpy="0 0 0" xyz="0 0 0.32" />
    <limit effort="30" velocity="1.0" lower="-1.5707963267948966" upper="1.5707963267948966" />
  </joint>

  <link name="pelvis_link">
    <visual>
      <geometry>
        <mesh filename="package://servicebot_description/meshes/Pelvis.obj" />
      </geometry>
    </visual>
    <collision>
      <origin rpy="0 0 0" xyz="0 0 -0.05"/>
      <geometry>
        <cylinder radius="0.1" length="0.18"/>
      </geometry>
    </collision>
    <inertial>
      <mass value="1"/>
      <inertia ixx="0.00545701" izz="0.00845138" iyy="0.00759291" ixy="0" ixz="0" iyz="0"/>
    </inertial>
  </link>

  <joint name="pelvis_fixedjoint" type="fixed">
    <parent link="base_link"/>
    <child link="pelvis_link"/>
    <origin rpy="0 0 0" xyz="0 0.00 -0.12"/>
  </joint>

  <link name="left_thigh_link">
    <visual>
      <geometry>
        <mesh filename="package://servicebot_description/meshes/Thigh_Left.obj" />
      </geometry>
    </visual>
    <collision>
      <origin rpy="0 0 0" xyz="0 0 -0.01"/>
      <geometry>
        <cylinder radius="0.12" length="0.25"/>
      </geometry>
    </collision>
    <inertial>
      <origin xyz="0 0 -0.1" rpy="0 0 0"/>
      <mass value="1"/>
      <inertia ixx="0.00886299" iyy="0.00886299" izz="0.00679615" ixy="0" ixz="0" iyz="0"/>
    </inertial>
  </link>

  <joint name="left_thigh_joint" type="fixed">
    <parent link="pelvis_link"/>
    <child link="left_thigh_link"/>
    <origin rpy="0.000 -0.640 0.000" xyz="0.017285 0.12 -0.11"/>
  </joint>

  <link name="right_thigh_link">
    <visual>
      <geometry>
        <mesh filename="package://servicebot_description/meshes/Thigh_Right.obj" />
      </geometry>
    </visual>
    <collision>
      <origin rpy="0 0 0" xyz="0 0 -0.01"/>
      <geometry>
        <cylinder radius="0.12" length="0.25"/>
      </geometry>
    </collision>
    <inertial>
      <origin xyz="0 0 -0.1" rpy="0 0 0"/>
      <mass value="1"/>
      <inertia ixx="0.00886299" iyy="0.00886299" izz="0.00679615" ixy="0" ixz="0" iyz="0"/>
    </inertial>
  </link>

  <joint name="right_thigh_joint" type="fixed">
    <parent link="pelvis_link"/>
    <child link="right_thigh_link"/>
    <origin rpy="0.000 -0.640 0.000" xyz="0.017285 -0.12 -0.11"/>

  </joint>

  <link name="left_upper_leg_link">
    <visual>
      <geometry>
        <mesh filename="package://servicebot_description/meshes/Calf_Left.obj" />
      </geometry>
    </visual>
    <collision>
      <origin rpy="0 0 0" xyz="0 0 -0.13"/>
      <geometry>
        <cylinder radius="0.12" length="0.33"/>
      </geometry>
    </collision>
    <inertial>
      <mass value="0.5"/>
      <inertia ixx="0.00466963" iyy="0.00466963" izz="0.00280397" ixy="0" ixz="0" iyz="0"/>
    </inertial>
  </link>

  <joint name="left_upper_leg_joint" type="fixed">
    <axis xyz="0 1 0"/>
    <parent link="left_thigh_link"/>
    <child link="left_upper_leg_link"/>
    <origin rpy="0.000 0.785 0.000" xyz="0.011 0.005 -0.106"/>
  </joint>


  <link name="right_upper_leg_link">
    <visual>
      <geometry>
        <mesh filename="package://servicebot_description/meshes/Calf_Left.obj" />
      </geometry>
    </visual>
    <collision>
      <origin rpy="0 0 0" xyz="0 0 -0.13"/>
      <geometry>
        <cylinder radius="0.12" length="0.33"/>
      </geometry>
    </collision>
    <inertial>
      <mass value="0.5"/>
      <inertia ixx="0.00466963" iyy="0.00466963" izz="0.00280397" ixy="0" ixz="0" iyz="0"/>
    </inertial>
  </link>

  <joint name="right_upper_leg_joint" type="fixed">
    <axis xyz="0 1 0"/>
    <parent link="right_thigh_link"/>
    <child link="right_upper_leg_link"/>
    <origin rpy="0.000 0.785 0.000" xyz="0.011 -0.005 -0.106"/>
  </joint>

  <link name="left_foot_link">
    <visual>
      <geometry>
        <mesh filename="package://servicebot_description/meshes/Foot_Left.obj" />
      </geometry>
    </visual>
    <collision>
      <geometry>
        <box size="0.35 0.2 0.15" />
      </geometry>
    </collision>
    <inertial>
      <mass value="0.001"/>
      <inertia ixx="1.0e-02" iyy="1.0e-06" izz="1.0e-06" ixy="0" ixz="0" iyz="0"/>
    </inertial>
  </link>

  <joint name="left_foot_joint" type="fixed">
    <parent link="left_upper_leg_link"/>
    <child link="left_foot_link"/>
    <origin rpy="0.000 -0.160 0.000" xyz="0.03 0 -0.335"/>
  </joint>

  <link name="right_foot_link">
    <visual>
      <geometry>
        <mesh filename="package://servicebot_description/meshes/Foot_Left.obj" />
      </geometry>
    </visual>
    <collision>
      <geometry>
        <box size="0.35 0.2 0.15" />
      </geometry>
    </collision>
    <inertial>
      <mass value="0.001"/>
      <inertia ixx="1.0e-02" iyy="1.0e-06" izz="1.0e-06" ixy="0" ixz="0" iyz="0"/>
    </inertial>
  </link>

  <joint name="right_foot_joint" type="fixed">
    <parent link="right_upper_leg_link"/>
    <child link="right_foot_link"/>
    <origin rpy="0.000 -0.160 0.000" xyz="0.03 0 -0.335"/>
  </joint>

<!-- Wheels -->

  <link name="left_wheel_link">
    <visual>
      <geometry>
        <mesh filename="package://servicebot_description/meshes/Wheel_Left.obj" />
      </geometry>
    </visual>
    <collision>
      <geometry>
        <sphere radius="0.103"/>
      </geometry>
    </collision>
    <inertial>
      <mass value="0.3"/>
      <inertia iyy="0.00211023" izz="0.00142144" ixx="0.00142144" ixy="0" ixz="0" iyz="0"/>
    </inertial>
  </link>

  <joint name="left_wheel_joint" type="continuous">
    <axis xyz="0 1 0"/>
    <parent link="left_foot_link"/>
    <child link="left_wheel_link"/>
    <origin rpy="0 0 0" xyz="0 0 0"/>
  </joint>

  <link name="right_wheel_link">
    <visual>
      <geometry>
        <mesh filename="package://servicebot_description/meshes/Wheel_Left.obj" />
      </geometry>
    </visual>
    <collision>
      <geometry>
        <sphere radius="0.103"/>
      </geometry>
    </collision>
    <inertial>
      <mass value="0.3"/>
      <inertia iyy="0.00211023" izz="0.00142144" ixx="0.00142144" ixy="0" ixz="0" iyz="0"/>
    </inertial>
  </link>

  <joint name="right_wheel_joint" type="continuous">
    <axis xyz="0 1 0"/>
    <parent link="right_foot_link"/>
    <child link="right_wheel_link"/>
    <origin rpy="0 0 0" xyz="0 0 0"/>
  </joint>

  <link name="left_caster_wheel_link">
    <visual>
      <geometry>
        <mesh filename="package://servicebot_description/meshes/CasterWheel_Left.obj" />
      </geometry>
    </visual>
    <collision>
      <geometry>
        <sphere radius="0.033"/>
      </geometry>
    </collision>
    <inertial>
      <mass value="0.03"/>
      <inertia ixx="0.00001324" iyy="0.00001955" izz="0.00001304" ixy="0" ixz="0.0" iyz="0"/>
    </inertial>
  </link>

  <joint name="left_caster_wheel_joint" type="continuous">
    <axis xyz="0 1 0"/>
    <parent link="left_foot_link"/>
    <child link="left_caster_wheel_link"/>
    <origin rpy="0 0 0" xyz="-0.142 0 -0.07"/>
  </joint>

  <link name="right_caster_wheel_link">
    <visual>
      <geometry>
        <mesh filename="package://servicebot_description/meshes/CasterWheel_Left.obj" />
      </geometry>
    </visual>
    <collision>
      <geometry>
        <sphere radius="0.033"/>
      </geometry>
    </collision>
    <inertial>
      <mass value="0.03"/>
      <inertia ixx="0.00001324" iyy="0.00001955" izz="0.00001304" ixy="0" ixz="0.0" iyz="0"/>
    </inertial>
  </link>

  <joint name="right_caster_wheel_joint" type="continuous">
    <axis xyz="0 1 0"/>
    <parent link="right_foot_link"/>
    <child link="right_caster_wheel_link"/>
    <origin rpy="0 0 0" xyz="-0.142 0 -0.07"/>
  </joint>


<!-- Arms -->
  <link name="left_shoulder_link">
    <visual>
      <geometry>
        <mesh filename="package://servicebot_description/meshes/Shoulder_Left.obj" />
      </geometry>
    </visual>
    <collision>
      <origin rpy="1.5707963267948966 0 0" xyz="0 0.01 0.01"/>
      <geometry>
        <cylinder radius="0.08" length="0.10"/>
      </geometry>
    </collision>
    <inertial>
      <mass value="0.001"/>
      <inertia ixx="1.0e-02" iyy="1.0e-06" izz="1.0e-06" ixy="0" ixz="0" iyz="0"/>
    </inertial>
  </link>

  <joint name="left_shoulder_joint" type="fixed">
    <!--axis xyz="0 1 0"/-->
    <parent link="base_link"/>
    <child link="left_shoulder_link"/>
    <origin rpy="0 -0.55 0" xyz="0 0.1737 0.115"/>
    <!--limit effort="30" velocity="1.0" lower="-0.55" upper="-0.55" /-->
  </joint>

  <link name="right_shoulder_link">
    <visual>
      <geometry>
        <mesh filename="package://servicebot_description/meshes/Shoulder_Right.obj" />
      </geometry>
    </visual>
    <collision>
      <origin rpy="1.5707963267948966 0 0" xyz="0 -0.01 0.01"/>
      <geometry>
        <cylinder radius="0.08" length="0.10"/>
      </geometry>
    </collision>
    <inertial>
      <mass value="0.001"/>
      <inertia ixx="1.0e-02" iyy="1.0e-06" izz="1.0e-06" ixy="0" ixz="0" iyz="0"/>
    </inertial>
  </link>

  <joint name="right_shoulder_joint" type="fixed">
    <!--axis xyz="0 1 0"/-->
    <parent link="base_link"/>
    <child link="right_shoulder_link"/>
    <origin rpy="0 -0.55 0" xyz="0 -0.1737 0.115"/>
    <!--limit effort="30" velocity="1.0" lower="-0.55" upper="-0.55" /-->
  </joint>


  <link name="left_upper_arm_link">
    <visual>
      <geometry>
        <mesh filename="package://servicebot_description/meshes/UpperArm_Left.obj" />
      </geometry>
    </visual>
    <collision>
      <origin rpy="1.5707963267948966 0 0" xyz="0 0.05 0.0"/>
      <geometry>
        <cylinder radius="0.065" length="0.15"/>
      </geometry>
    </collision>
    <inertial>
      <mass value="0.2"/>
      <inertia ixx="1.0e-02" iyy="1.0e-06" izz="1.0e-06" ixy="0" ixz="0" iyz="0"/>
    </inertial>
  </link>

  <joint name="left_upper_arm_joint" type="fixed">
    <!--axis xyz="-1 0 0"/-->
    <parent link="left_shoulder_link"/>
    <child link="left_upper_arm_link"/>
    <origin rpy="-1.35 0 0" xyz="0 0.015 0.001"/>
    <!--limit effort="30" velocity="1.0" lower="1.35" upper="1.35" /-->
  </joint>

  <link name="right_upper_arm_link">
    <visual>
      <origin rpy="0 0 3.14159265" xyz="0 0 0"/>
      <geometry>
        <mesh filename="package://servicebot_description/meshes/UpperArm_Left.obj" />
      </geometry>
    </visual>
    <collision>
      <origin rpy="1.5707963267948966 0 0" xyz="0 -0.02 0.0"/>
      <geometry>
        <cylinder radius="0.065" length="0.22"/>
      </geometry>
    </collision>
    <inertial>
      <mass value="0.2"/>
      <inertia ixx="1.0e-02" iyy="1.0e-06" izz="1.0e-06" ixy="0" ixz="0" iyz="0"/>
    </inertial>
  </link>

  <joint name="right_upper_arm_joint" type="fixed">
    <!--axis xyz="1 0 0"/-->
    <parent link="right_shoulder_link"/>
    <child link="right_upper_arm_link"/>
    <origin rpy="1.35 0 0" xyz="0 -0.015 0.001"/>
    <!--limit effort="30" velocity="1.0" lower="1.35" upper="1.35" /-->
  </joint>

  <link name="left_elbow_attach_link">
    <visual>
      <geometry>
        <mesh filename="package://servicebot_description/meshes/Elbow_Left.obj" />
      </geometry>
    </visual>
    <inertial>
      <mass value="0.15"/>
      <inertia ixx="1.0e-02" iyy="1.0e-06" izz="1.0e-06" ixy="0" ixz="0" iyz="0"/>
    </inertial>
  </link>

  <joint name="left_elbow_attach_joint" type="fixed">
    <parent link="left_upper_arm_link"/>
    <child link="left_elbow_attach_link"/>
    <origin rpy="0 0 0" xyz="0 0.105 0.001"/>
  </joint>

  <link name="right_elbow_attach_link">
    <visual>
      <origin rpy="0 0 3.14159265" xyz="0 0 0"/>
      <geometry>
        <mesh filename="package://servicebot_description/meshes/Elbow_Left.obj" />
      </geometry>
    </visual>
    <inertial>
      <mass value="0.15"/>
      <inertia ixx="1.0e-02" iyy="1.0e-06" izz="1.0e-06" ixy="0" ixz="0" iyz="0"/>
    </inertial>
  </link>

  <joint name="right_elbow_attach_joint" type="fixed">
    <parent link="right_upper_arm_link"/>
    <child link="right_elbow_attach_link"/>
    <origin rpy="0 0 0" xyz="0 -0.105 0.001"/>
  </joint>


  <link name="left_forearm_link">
    <visual>
      <geometry>
        <mesh filename="package://servicebot_description/meshes/Forearm_Left.obj" />
      </geometry>
    </visual>
    <collision>
      <origin rpy="1.5707963267948966 0 0" xyz="0 0.04 0.0"/>
      <geometry>
        <cylinder radius="0.06" length="0.16"/>
      </geometry>
    </collision>
    <inertial>
      <mass value="0.2"/>
      <inertia ixx="1.0e-02" iyy="1.0e-06" izz="1.0e-06" ixy="0" ixz="0" iyz="0"/>
    </inertial>
  </link>

  <joint name="left_elbow_joint" type="fixed">
    <!--axis xyz="0 0 1"/-->
    <parent link="left_elbow_attach_link"/>
    <child link="left_forearm_link"/>
    <origin rpy="0 0 -0.50" xyz="-0.006 0.055 -0.001"/>
    <!--limit effort="30" velocity="1.0" lower="-0.5" upper="-0.5" /-->
  </joint>

  <link name="right_forearm_link">
    <visual>
      <origin rpy="0 0 0" xyz="0 0 0"/>
      <geometry>
        <mesh filename="package://servicebot_description/meshes/Forearm_Right.obj" />
      </geometry>
    </visual>
    <collision>
      <origin rpy="1.5707963267948966 0 0" xyz="0 -0.04 0.0"/>
      <geometry>
        <cylinder radius="0.06" length="0.16"/>
      </geometry>
    </collision>
    <inertial>
      <mass value="0.2"/>
      <inertia ixx="1.0e-02" iyy="1.0e-06" izz="1.0e-06" ixy="0" ixz="0" iyz="0"/>
    </inertial>
  </link>

  <joint name="right_elbow_joint" type="fixed">
    <!--axis xyz="0 0 -1"/-->
    <parent link="right_elbow_attach_link"/>
    <child link="right_forearm_link"/>
    <origin rpy="0 0 0.5" xyz="-0.006 -0.055 -0.001"/>
    <!--limit effort="30" velocity="1.0" lower="-0.5" upper="-0.5" /-->
  </joint>

  <link name="left_hand_link">
    <visual>
      <geometry>
        <mesh filename="package://servicebot_description/meshes/Hand_Left.obj" />
      </geometry>
    </visual>
    <collision>
      <origin rpy="0 0 0" xyz="0 0.05 0.0"/>
      <geometry>
        <box size="0.07 0.14 0.08"/>
      </geometry>
    </collision>
    <inertial>
      <mass value="0.1"/>
      <inertia ixx="1.0e-02" iyy="1.0e-06" izz="1.0e-06" ixy="0" ixz="0" iyz="0"/>
    </inertial>
  </link>

  <joint name="left_hand_fixedjoint" type="fixed">
    <parent link="left_forearm_link"/>
    <child link="left_hand_link"/>
    <origin rpy="0 0 0" xyz="0.005 0.095 0.0"/>
  </joint>

  <link name="right_hand_link">
    <visual>
      <geometry>
        <mesh filename="package://servicebot_description/meshes/Hand_Right.obj" />
      </geometry>
    </visual>
    <collision>
      <origin rpy="0 0 0" xyz="0 -0.05 0.0"/>
      <geometry>
        <box size="0.07 0.14 0.08"/>
      </geometry>
    </collision>
    <inertial>
      <mass value="0.1"/>
      <inertia ixx="1.0e-02" iyy="1.0e-06" izz="1.0e-06" ixy="0" ixz="0" iyz="0"/>
    </inertial>
  </link>

  <joint name="right_hand_fixedjoint" type="fixed">
    <parent link="right_forearm_link"/>
    <child link="right_hand_link"/>
    <origin rpy="0 0 0" xyz="0.005 -0.095 0.0"/>
  </joint>

  <link name="left_lower_hand_link">
    <visual>
      <geometry>
        <mesh filename="package://servicebot_description/meshes/LowerHand_Left.obj" />
      </geometry>
    </visual>
    <collision>
      <origin rpy="0 0 0" xyz="0 0.04 0.0"/>
      <geometry>
        <box size="0.07 0.12 0.04"/>
      </geometry>
    </collision>
    <inertial>
      <mass value="0.1"/>
      <inertia ixx="1.0e-02" iyy="1.0e-06" izz="1.0e-06" ixy="0" ixz="0" iyz="0"/>
    </inertial>
  </link>

  <joint name="left_gripper_joint" type="fixed">
    <!--axis xyz="1 0 0"/-->
    <parent link="left_hand_link"/>
    <child link="left_lower_hand_link"/>
    <origin rpy="0 0 0" xyz="0.00 0.02 -0.025"/>
    <!--limit effort="30" velocity="1.0" lower="-0.7853981633974483" upper="0" /-->
  </joint>

  <link name="right_lower_hand_link">
    <visual>
      <geometry>
        <mesh filename="package://servicebot_description/meshes/LowerHand_Right.obj" />
      </geometry>
    </visual>
    <collision>
      <origin rpy="0 0 0" xyz="0 -0.04 0.0"/>
      <geometry>
        <box size="0.07 0.12 0.04"/>
      </geometry>
    </collision>
    <inertial>
      <mass value="0.1"/>
      <inertia ixx="1.0e-02" iyy="1.0e-06" izz="1.0e-06" ixy="0" ixz="0" iyz="0"/>
    </inertial>
  </link>
  <joint name="right_gripper_joint" type="fixed">
    <!--axis xyz="-1 0 0"/-->
    <parent link="right_hand_link"/>
    <child link="right_lower_hand_link"/>
    <origin rpy="0 0 0" xyz="0.00 -0.02 -0.025"/>
    <!--limit effort="30" velocity="1.0" lower="-0.7853981633974483" upper="0" /-->
  </joint>


  <link name="front_camera_frame">
    <inertial>
      <mass value="0.001"/>
      <inertia ixx="1.0e-06" iyy="1.0e-06" izz="1.0e-06" ixy="0" ixz="0" iyz="0"/>
    </inertial>
  </link>
  <joint name="front_camera_fixedjoint" type="fixed">
    <parent link="head_link"/>
    <child link="front_camera_frame"/>
    <!--origin rpy="-1.57079632679 0 -1.57079632679" xyz="0.1 0 0"/-->
    <origin xyz="0.1 0 0" rpy="0 0 0"/>
  </joint>
  <link name="front_camera_optical_frame">
    <inertial>
      <mass value="0.001"/>
      <inertia ixx="1.0e-06" iyy="1.0e-06" izz="1.0e-06" ixy="0" ixz="0" iyz="0"/>
    </inertial>
  </link>
  <joint name="front_camera_optical_fixedjoint" type="fixed">
    <parent link="front_camera_frame"/>
    <child link="front_camera_optical_frame"/>
    <origin xyz="0 0 0" rpy="-1.57079632679 0 -1.57079632679"/>
    <!--origin rpy="0 0 0" xyz="0.1 0 0"/-->
  </joint>
  <link name="rear_camera_frame">
    <inertial>
      <mass value="0.001"/>
      <inertia ixx="1.0e-06" iyy="1.0e-06" izz="1.0e-06" ixy="0" ixz="0" iyz="0"/>
    </inertial>
  </link>
  <joint name="rear_camera_fixedjoint" type="fixed">
    <parent link="head_link"/>
    <child link="rear_camera_frame"/>
    <origin xyz="-0.1 0 0" rpy="0 0 3.14159265"/>
  </joint>
  <link name="rear_camera_optical_frame">
    <inertial>
      <mass value="0.001"/>
      <inertia ixx="1.0e-06" iyy="1.0e-06" izz="1.0e-06" ixy="0" ixz="0" iyz="0"/>
    </inertial>
  </link>
  <joint name="rear_camera_optical_fixedjoint" type="fixed">
    <parent link="rear_camera_frame"/>
    <child link="rear_camera_optical_frame"/>
    <origin xyz="0 0 0" rpy="-1.57079632679 0 -1.57079632679"/>
  </joint>
  <link name="lidar_frame">
    <inertial>
      <mass value="0.001"/>
      <inertia ixx="1.0e-06" iyy="1.0e-06" izz="1.0e-06" ixy="0" ixz="0" iyz="0"/>
    </inertial>
  </link>
  <joint name="neck_lidar_fixedjoint" type="fixed">
    <parent link="base_link"/>
    <child link="lidar_frame"/>
    <origin rpy="0 0 0" xyz="0.05 0 0.22" />
    <!--origin xyz="0 0 0" rpy="0 0 0"/-->
  </joint>

  <!-- Inflations -->

  <link name="inflation_people">
    <inertial>
      <mass value="0.001"/>
      <inertia ixx="1.0e-06" iyy="1.0e-06" izz="1.0e-06" ixy="0" ixz="0" iyz="0"/>
    </inertial>
    <collision>
      <origin rpy="0 0 -0.08" xyz="0 0 0"/>
      <geometry>
        <cylinder radius="0.75" length="1.07"/>
      </geometry>
    </collision>
  </link>
  <gazebo reference="inflation_people">
    <collision>
      <surface>
        <contact>
          <collide_without_contact>true</collide_without_contact>
        </contact>
      </surface>
    </collision>
  </gazebo>
  <joint name="inflation_people_fixedjoint" type="fixed">
    <parent link="base_link"/>
    <child link="inflation_people"/>
  </joint>
  <gazebo reference='inflation_people_fixedjoint'>
    <preserveFixedJoint>true</preserveFixedJoint>
  </gazebo>

  <link name="inflation_obj">
    <inertial>
      <mass value="0.001"/>
      <inertia ixx="1.0e-06" iyy="1.0e-06" izz="1.0e-06" ixy="0" ixz="0" iyz="0"/>
    </inertial>
    <collision>
      <origin rpy="0 0 -0.08" xyz="0 0 0"/>
      <geometry>
        <cylinder radius="0.35" length="1.07"/>
      </geometry>
    </collision>
  </link>
  <gazebo reference="inflation_obj">
    <collision>
      <surface>
        <contact>
          <collide_without_contact>true</collide_without_contact>
        </contact>
      </surface>
    </collision>
  </gazebo>
  <joint name="inflation_obj_fixedjoint" type="fixed">
    <parent link="base_link"/>
    <child link="inflation_obj"/>
  </joint>
  <gazebo reference='inflation_obj_fixedjoint'>
    <preserveFixedJoint>true</preserveFixedJoint>
  </gazebo>

  <!-- /Inflations -->

  <gazebo>
    <plugin name="differential_drive_controller" filename="libgazebo_ros_diff_drive.so">
      <!--robotNamespace>servicebot</robotNamespace-->
      <legacyMode>false</legacyMode>
      <publishTf>true</publishTf>
      <publishWheelTF>true</publishWheelTF>
      <leftJoint>left_wheel_joint</leftJoint>
      <rightJoint>right_wheel_joint</rightJoint>
      <robotBaseFrame>base_footprint</robotBaseFrame>
      <wheelSeparation>0.25</wheelSeparation>
      <wheelDiameter>0.206</wheelDiameter>
      <!--wheelAcceleration>0.3</wheelAcceleration-->
      <publishWheelJointState>true</publishWheelJointState>
      <odometryTopic>/servicebot/odom</odometryTopic>
      <commandTopic>/servicebot/cmd_vel</commandTopic>
      <odometrySource>encoder</odometrySource>
    </plugin>
  </gazebo>

  <gazebo>
    <plugin name="rfid_plugin" filename="libVicinityPlugin.so">
      <topicName>rfid</topicName>
      <updateRate>10</updateRate>
      <threshold>2</threshold>
    </plugin>
  </gazebo>

  <gazebo reference="front_camera_frame">
    <sensor type="camera" name="FrontCamera">
        <update_rate>24.0</update_rate>
        <camera name="front_camera">
            <horizontal_fov>1.06290551</horizontal_fov>
            <image>
                <width>640</width>
                <height>480</height>
                <format>R8G8B8</format>
            </image>
            <clip>
                <near>0.3</near>
                <far>500</far>
            </clip>
            <noise>
                <type>gaussian</type>
                <mean>0.0</mean>
                <stddev>0.007</stddev>
            </noise>
        </camera>
        <plugin name="camera_controller" filename="libgazebo_ros_camera.so">
            <robotNamespace>servicebot</robotNamespace>
            <alwaysOn>true</alwaysOn>
            <updateRate>24.0</updateRate>
            <cameraName>camera_front</cameraName>
            <imageTopicName>image_raw</imageTopicName>
            <cameraInfoTopicName>camera_info</cameraInfoTopicName>
            <frameName>front_camera_optical_frame</frameName>
            <hackBaseline>0.07</hackBaseline>
            <distortionK1>-0.0545211</distortionK1>
            <distortionK2>0.06919734</distortionK2>
            <distortionK3>-0.0241095</distortionK3>
            <distortionT1>-0.0112245</distortionT1>
            <distortionT2>0.0</distortionT2>
        </plugin>
    </sensor>
  </gazebo>
  <gazebo reference="rear_camera_frame">
    <sensor type="camera" name="RearCamera">
        <update_rate>24.0</update_rate>
        <camera name="rear_camera">
            <horizontal_fov>1.06290551</horizontal_fov>
            <image>
                <width>640</width>
                <height>480</height>
                <format>R8G8B8</format>
            </image>
            <clip>
                <near>0.3</near>
                <far>500</far>
            </clip>
            <noise>
                <type>gaussian</type>
                <mean>0.0</mean>
                <stddev>0.007</stddev>
            </noise>
        </camera>
        <plugin name="camera_controller" filename="libgazebo_ros_camera.so">
            <robotNamespace>servicebot</robotNamespace>
            <alwaysOn>true</alwaysOn>
            <updateRate>24.0</updateRate>
            <cameraName>camera_rear</cameraName>
            <imageTopicName>image_raw</imageTopicName>
            <cameraInfoTopicName>camera_info</cameraInfoTopicName>
            <frameName>rear_camera_optical_frame</frameName>
            <hackBaseline>0.07</hackBaseline>
            <distortionK1>-0.0545211</distortionK1>
            <distortionK2>0.06919734</distortionK2>
            <distortionK3>-0.0241095</distortionK3>
            <distortionT1>-0.0112245</distortionT1>
            <distortionT2>0.0</distortionT2>
        </plugin>
    </sensor>
  </gazebo>
  <gazebo reference="lidar_frame">
    <sensor type="gpu_ray" name="lidar">
      <visualize>false</visualize>
      <update_rate>10</update_rate>
      <ray>
        <scan>
          <horizontal>
            <samples>1875</samples>
            <resolution>1</resolution>
            <min_angle>-2.0943951023931953</min_angle>
            <max_angle>2.0943951023931953</max_angle>
          </horizontal>
        </scan>
        <range>
          <min>0.1</min>
          <max>30.0</max>
          <resolution>0.001</resolution>
        </range>
        <noise>
          <type>gaussian</type>
          <mean>0.0</mean>
          <stddev>0.008</stddev>
        </noise>
      </ray>
      <plugin name="gazebo_ros_laser_controller" filename="libgazebo_ros_gpu_laser.so">
        <robotNamespace>servicebot</robotNamespace>
        <topicName>scan</topicName>
        <frameName>/lidar_frame</frameName>
        <min_range>0.1</min_range>
        <max_range>30.0</max_range>
        <gaussianNoise>0.008</gaussianNoise>
      </plugin>
    </sensor>
  </gazebo>
  <gazebo reference="base_link">
    <gravity>true</gravity>
    <sensor name="imu_sensor" type="imu">
      <always_on>true</always_on>
      <update_rate>100</update_rate>
      <visualize>true</visualize>
      <topic>imu</topic>
      <plugin filename="libgazebo_ros_imu_sensor.so" name="imu_plugin">
        <!--robotNamespace>servicebot</robotNamespace-->
        <topicName>servicebot/imu</topicName>
        <bodyName>base_link</bodyName>
        <updateRateHZ>10.0</updateRateHZ>
        <gaussianNoise>0.0</gaussianNoise>
        <xyzOffset>0 0 0</xyzOffset>
        <rpyOffset>0 0 0</rpyOffset>
        <frameName>base_link</frameName>
      </plugin>
    </sensor>
  </gazebo>

  <gazebo reference="base_link">
    <mu1>0.5</mu1>
    <mu2>0.5</mu2>
    <selfCollide>false</selfCollide>
    <turnGravityOff>false</turnGravityOff>
  </gazebo>
  <gazebo reference="head_link">
    <mu1>0.5</mu1>
    <mu2>0.5</mu2>
    <selfCollide>false</selfCollide>
    <turnGravityOff>false</turnGravityOff>
  </gazebo>
  <gazebo reference="head_pan_link">
    <mu1>0.5</mu1>
    <mu2>0.5</mu2>
    <selfCollide>false</selfCollide>
    <turnGravityOff>false</turnGravityOff>
  </gazebo>
  <gazebo reference="pelvis_link">
    <mu1>0.5</mu1>
    <mu2>0.5</mu2>
    <selfCollide>false</selfCollide>
    <turnGravityOff>false</turnGravityOff>
  </gazebo>
  <gazebo reference="left_upper_leg_link">
    <mu1>0.5</mu1>
    <mu2>0.5</mu2>
    <selfCollide>false</selfCollide>
    <turnGravityOff>false</turnGravityOff>
  </gazebo>
  <gazebo reference="right_upper_leg_link">
    <mu1>0.5</mu1>
    <mu2>0.5</mu2>
    <selfCollide>false</selfCollide>
    <turnGravityOff>false</turnGravityOff>
  </gazebo>
  <gazebo reference="left_foot_link">
    <mu1>0.5</mu1>
    <mu2>0.5</mu2>
    <selfCollide>false</selfCollide>
    <turnGravityOff>false</turnGravityOff>
  </gazebo>
  <gazebo reference="right_foot_link">
    <mu1>0.5</mu1>
    <mu2>0.5</mu2>
    <selfCollide>false</selfCollide>
    <turnGravityOff>false</turnGravityOff>
  </gazebo>
  <gazebo reference="left_wheel_link">
    <mu1>1</mu1>
    <mu2>1</mu2>
    <selfCollide>false</selfCollide>
    <turnGravityOff>false</turnGravityOff>
    <minDepth>0.005</minDepth>
    <kp>1e6</kp>
  </gazebo>
  <gazebo reference="right_wheel_link">
    <mu1>1</mu1>
    <mu2>1</mu2>
    <selfCollide>false</selfCollide>
    <turnGravityOff>false</turnGravityOff>
    <minDepth>0.005</minDepth>
    <kp>1e6</kp>
  </gazebo>
  <gazebo reference="left_caster_wheel_link">
    <mu1>1</mu1>
    <mu2>1</mu2>
    <selfCollide>false</selfCollide>
    <turnGravityOff>false</turnGravityOff>
    <minDepth>0.0001</minDepth>
    <kp>1e6</kp>
  </gazebo>
  <gazebo reference="right_caster_wheel_link">
    <mu1>0.8</mu1>
    <mu2>0.8</mu2>
    <selfCollide>false</selfCollide>
    <turnGravityOff>false</turnGravityOff>
    <minDepth>0.0001</minDepth>
    <kp>1e6</kp>
  </gazebo>
  <gazebo reference="left_upper_arm_link">
    <mu1>0.5</mu1>
    <mu2>0.5</mu2>
    <selfCollide>false</selfCollide>
    <turnGravityOff>false</turnGravityOff>
  </gazebo>
  <gazebo reference="right_upper_arm_link">
    <mu1>0.5</mu1>
    <mu2>0.5</mu2>
    <selfCollide>false</selfCollide>
    <turnGravityOff>false</turnGravityOff>
  </gazebo>
  <gazebo reference="left_forearm_link">
    <mu1>0.5</mu1>
    <mu2>0.5</mu2>
    <selfCollide>false</selfCollide>
    <turnGravityOff>false</turnGravityOff>
  </gazebo>
  <gazebo reference="right_forearm_link">
    <mu1>0.5</mu1>
    <mu2>0.5</mu2>
    <selfCollide>false</selfCollide>
    <turnGravityOff>false</turnGravityOff>
  </gazebo>

<!-- Transmissions -->
	<transmission name="head_tilt_Transmission">
		<type>transmission_interface/SimpleTransmission</type>
		<joint name="head_tilt_joint">
			  <hardwareInterface>hardware_interface/EffortJointInterface</hardwareInterface>
		</joint>
    <actuator name="head_tilt_Motor">
			  <hardwareInterface>hardware_interface/EffortJointInterface</hardwareInterface>
			<mechanicalReduction>1</mechanicalReduction>
		</actuator>
	</transmission>
	<transmission name="head_pan_Transmission">
		<type>transmission_interface/SimpleTransmission</type>
		<joint name="head_pan_joint">
			    <hardwareInterface>hardware_interface/EffortJointInterface</hardwareInterface>
		</joint>
    <actuator name="head_pan_Motor">
			<hardwareInterface>hardware_interface/EffortJointInterface</hardwareInterface>
			<mechanicalReduction>1</mechanicalReduction>
		</actuator>
	</transmission>
	<transmission name="left_caster_wheel_Transmission">
		<type>transmission_interface/SimpleTransmission</type>
		<joint name="left_caster_wheel_joint">
			  <hardwareInterface>hardware_interface/PositionJointInterface</hardwareInterface>
		</joint>
    <actuator name="left_caster_wheel_Motor">
			<hardwareInterface>hardware_interface/PositionJointInterface</hardwareInterface>
			<mechanicalReduction>1</mechanicalReduction>
		</actuator>
	</transmission>
	<transmission name="right_caster_wheel_Transmission">
		<type>transmission_interface/SimpleTransmission</type>
		<joint name="right_caster_wheel_joint">
      <hardwareInterface>hardware_interface/PositionJointInterface</hardwareInterface>
		</joint>
    <actuator name="right_caster_wheel_Motor">
			<hardwareInterface>hardware_interface/PositionJointInterface</hardwareInterface>
			<mechanicalReduction>1</mechanicalReduction>
		</actuator>
	</transmission>
  <gazebo>
     <plugin filename="libgazebo_ros_control.so" name="gazebo_ros_control">
         <robotNamespace>servicebot</robotNamespace>
         <robotSimType>gazebo_ros_control/DefaultRobotHWSim</robotSimType>
     </plugin>
  </gazebo>
</robot>
